2024-12-29 09:45:08,628 INFO    MainThread:54321 [wandb_setup.py:_flush():68] Current SDK version is 0.19.1
2024-12-29 09:45:08,629 INFO    MainThread:54321 [wandb_setup.py:_flush():68] Configure stats pid to 54321
2024-12-29 09:45:08,629 INFO    MainThread:54321 [wandb_setup.py:_flush():68] Loading settings from /home/harlab/.config/wandb/settings
2024-12-29 09:45:08,629 INFO    MainThread:54321 [wandb_setup.py:_flush():68] Loading settings from /home/harlab/1-ncsu/mass-dart-exo/python/wandb/settings
2024-12-29 09:45:08,629 INFO    MainThread:54321 [wandb_setup.py:_flush():68] Loading settings from environment variables
2024-12-29 09:45:08,629 INFO    MainThread:54321 [wandb_init.py:_log_setup():528] Logging user logs to /home/harlab/1-ncsu/mass-dart-exo/python/wandb/run-20241229_094508-5wcjjrrg/logs/debug.log
2024-12-29 09:45:08,629 INFO    MainThread:54321 [wandb_init.py:_log_setup():529] Logging internal logs to /home/harlab/1-ncsu/mass-dart-exo/python/wandb/run-20241229_094508-5wcjjrrg/logs/debug-internal.log
2024-12-29 09:45:08,629 INFO    MainThread:54321 [wandb_init.py:init():644] calling init triggers
2024-12-29 09:45:08,629 INFO    MainThread:54321 [wandb_init.py:init():650] wandb.init called with sweep_config: {}
config: {}
2024-12-29 09:45:08,629 INFO    MainThread:54321 [wandb_init.py:init():680] starting backend
2024-12-29 09:45:08,629 INFO    MainThread:54321 [wandb_init.py:init():684] sending inform_init request
2024-12-29 09:45:08,644 INFO    MainThread:54321 [backend.py:_multiprocessing_setup():104] multiprocessing start_methods=fork,spawn,forkserver, using: spawn
2024-12-29 09:45:08,644 INFO    MainThread:54321 [wandb_init.py:init():697] backend started and connected
2024-12-29 09:45:08,646 INFO    MainThread:54321 [wandb_init.py:init():790] updated telemetry
2024-12-29 09:45:08,653 INFO    MainThread:54321 [wandb_init.py:init():822] communicating run to backend with 90.0 second timeout
2024-12-29 09:45:09,667 ERROR   MainThread:54321 [wandb_init.py:init():849] encountered error: failed to upsert bucket: returned error 403 Forbidden: {"errors":[{"message":"permission denied","path":["upsertBucket"],"extensions":{"code":"PERMISSION_ERROR"}}],"data":{"upsertBucket":null}}
2024-12-29 09:45:09,668 ERROR   MainThread:54321 [wandb_init.py:init():1308] error in wandb.init()
Traceback (most recent call last):
  File "/home/harlab/anaconda3/envs/exo/lib/python3.8/site-packages/wandb/sdk/wandb_init.py", line 1298, in init
    return wi.init()
  File "/home/harlab/anaconda3/envs/exo/lib/python3.8/site-packages/wandb/sdk/wandb_init.py", line 855, in init
    raise error
wandb.errors.errors.CommError: failed to upsert bucket: returned error 403 Forbidden: {"errors":[{"message":"permission denied","path":["upsertBucket"],"extensions":{"code":"PERMISSION_ERROR"}}],"data":{"upsertBucket":null}}
2024-12-29 09:45:09,676 WARNING MsgRouterThr:54321 [router.py:message_loop():75] message_loop has been closed
